Workbook

Sheet Table
A1: Name | B1: Points
A2: Noonan | B2: =SUM('Noonan '!L:L) -> 28
A3: Daithi | B3: =SUM(Daithi!L:L) -> 27
A4: Mick | B4: =SUM(Mick!L:L) -> 26
A5: Owen | B5: =SUM(Owen!L:L) -> 25
A6: Kian | B6: =SUM(Kian!L:L) -> 25
A7: Mac | B7: =SUM(Mac!L:L) -> 24
A8: Garret | B8: =SUM(Garret!L:L) -> 20
A9: Reddy | B9: =SUM(Reddy!L:L) -> 19

Sheet Results
A1: =weekday(B1) -> 5 | B1: 46184 | C1: 0.83333333 | D1: Group A | E1: Mexico | F1: 2 | G1: 0 | H1: South Africa | I1: =F1&"-"&G1 -> 2-0 | J1: =F1-G1 -> 2
A2: =weekday(B2) -> 6 | B2: 46185 | C2: 0.125 | D2: Group A | E2: South Korea | F2: 2 | G2: 1 | H2: Czech Republic | I2: =F2&"-"&G2 -> 2-1 | J2: =F2-G2 -> 1
A3: =weekday(B3) -> 6 | B3: 46185 | C3: 0.83333333 | D3: Group B | E3: Canada | F3: 1 | G3: 1 | H3: Bosnia and Herzegovina | I3: =F3&"-"&G3 -> 1-1 | J3: =F3-G3 -> 0
A4: =weekday(B4) -> 7 | B4: 46186 | C4: 0.083333333 | D4: Group D | E4: USA | F4: 4 | G4: 1 | H4: Paraguay | I4: =F4&"-"&G4 -> 4-1 | J4: =F4-G4 -> 3
A5: =weekday(B5) -> 7 | B5: 46186 | C5: 0.83333333 | D5: Group B | E5: Qatar | F5: 1 | G5: 1 | H5: Switzerland | I5: =F5&"-"&G5 -> 1-1 | J5: =F5-G5 -> 0
A6: =weekday(B6) -> 7 | B6: 46186 | C6: 0.95833333 | D6: Group C | E6: Brazil | F6: 1 | G6: 1 | H6: Morocco | I6: =F6&"-"&G6 -> 1-1 | J6: =F6-G6 -> 0
A7: =weekday(B7) -> 1 | B7: 46187 | C7: 0.083333333 | D7: Group C | E7: Haiti | F7: 0 | G7: 1 | H7: Scotland | I7: =F7&"-"&G7 -> 0-1 | J7: =F7-G7 -> -1
A8: =weekday(B8) -> 1 | B8: 46187 | C8: 0.20833333 | D8: Group D | E8: Australia | F8: 2 | G8: 0 | H8: Türkiye | I8: =F8&"-"&G8 -> 2-0 | J8: =F8-G8 -> 2
A9: =weekday(B9) -> 1 | B9: 46187 | C9: 0.75 | D9: Group E | E9: Germany | F9: 7 | G9: 1 | H9: Curaçao | I9: =F9&"-"&G9 -> 7-1 | J9: =F9-G9 -> 6
A10: =weekday(B10) -> 1 | B10: 46187 | C10: 0.875 | D10: Group F | E10: Netherlands | F10: 2 | G10: 2 | H10: Japan | I10: =F10&"-"&G10 -> 2-2 | J10: =F10-G10 -> 0
A11: =weekday(B11) -> 2 | B11: 46188 | C11: 0 | D11: Group E | E11: Ivory Coast | F11: 1 | G11: 0 | H11: Ecuador | I11: =F11&"-"&G11 -> 1-0 | J11: =F11-G11 -> 1
A12: =weekday(B12) -> 2 | B12: 46188 | C12: 0.125 | D12: Group F | E12: Sweden | F12: 5 | G12: 1 | H12: Tunisia | I12: =F12&"-"&G12 -> 5-1 | J12: =F12-G12 -> 4
... A32: =weekday(B32) -> 7 | B32: 46193 | C32: 0.16666667 | D32: Group D | E32: Turkey | F32: 0 | G32: 1 | H32: Paraguay | I32: =F32&"-"&G32 -> 0-1 | J32: =F32-G32 -> -1
A33: =weekday(B33) -> 7 | B33: 46193 | C33: 0.75 | D33: Group F | E33: Netherlands | H33: Sweden | I33: =F33&"-"&G33 -> - | J33: =F33-G33 -> 0
A34: =weekday(B34) -> 7 | B34: 46193 | C34: 0.875 | D34: Group E | E34: Germany | H34: Ivory Coast | I34: =F34&"-"&G34 -> - | J34: =F34-G34 -> 0
A35: =weekday(B35) -> 1 | B35: 46194 | C35: 0.041666667 | D35: Group E | E35: Ecuador | H35: Curaçao | I35: =F35&"-"&G35 -> - | J35: =F35-G35 -> 0
A36: =weekday(B36) -> 1 | B36: 46194 | C36: 0.20833333 | D36: Group F | E36: Tunisia | H36: Japan | I36: =F36&"-"&G36 -> - | J36: =F36-G36 -> 0
A37: =weekday(B37) -> 1 | B37: 46194 | C37: 0.70833333 | D37: Group H | E37: Spain | H37: Saudi Arabia | I37: =F37&"-"&G37 -> - | J37: =F37-G37 -> 0
A38: =weekday(B38) -> 1 | B38: 46194 | C38: 0.83333333 | D38: Group G | E38: Belgium | H38: Iran | I38: =F38&"-"&G38 -> - | J38: =F38-G38 -> 0
A39: =weekday(B39) -> 1 | B39: 46194 | C39: 0.95833333 | D39: Group H | E39: Uruguay | H39: Cape Verde | I39: =F39&"-"&G39 -> - | J39: =F39-G39 -> 0
A40: =weekday(B40) -> 2 | B40: 46195 | C40: 0.083333333 | D40: Group G | E40: New Zealand | H40: Egypt | I40: =F40&"-"&G40 -> - | J40: =F40-G40 -> 0
A41: =weekday(B41) -> 2 | B41: 46195 | C41: 0.79166667 | D41: Group J | E41: Argentina | H41: Austria | I41: =F41&"-"&G41 -> - | J41: =F41-G41 -> 0
A42: =weekday(B42) -> 2 | B42: 46195 | C42: 0.95833333 | D42: Group I | E42: France | H42: Iraq | I42: =F42&"-"&G42 -> - | J42: =F42-G42 -> 0
A43: =weekday(B43) -> 3 | B43: 46196 | C43: 0.083333333 | D43: Group I | E43: Norway | H43: Senegal | I43: =F43&"-"&G43 -> - | J43: =F43-G43 -> 0
A44: =weekday(B44) -> 3 | B44: 46196 | C44: 0.20833333 | D44: Group J | E44: Jordan | H44: Algeria | I44: =F44&"-"&G44 -> - | J44: =F44-G44 -> 0
... A104: =weekday(B104) -> 1 | B104: 46222 | C104: 0.83333333 | D104: Final | E104: Winner Match 101 | H104: Winner Match 102 | I104: =F104&"-"&G104 -> - | J104: =F104-G104 -> 0

Sheet Games
G1: Daithi | H1: Kian | I1: Mick | J1: Owen | K1: Reddy | L1: Garret | M1: Mac | N1: Noonan
A2: =Results!B1 -> 46184 | B2: =Results!C1 -> 0.83333333 | C2: =Results!D1 -> Group A | D2: =Results!E1 -> Mexico | E2: =Results!I1 -> 2-0 | F2: =Results!H1 -> South Africa | G2: =Daithi!L2 -> 3 | H2: =Kian!L2 -> 1 | I2: =Mick!L2 -> 3 | J2: =Owen!L2 -> 1 | K2: =Reddy!L2 -> 3 | L2: =Garret!L2 -> 3 | M2: =Mac!L2 -> 1 | N2: ='Noonan '!L2 -> 0
A3: =Results!B2 -> 46185 | B3: =Results!C2 -> 0.125 | C3: =Results!D2 -> Group A | D3: =Results!E2 -> South Korea | E3: =Results!I2 -> 2-1 | F3: =Results!H2 -> Czech Republic | G3: =Daithi!L3 -> 0 | H3: =Kian!L3 -> 1 | I3: =Mick!L3 -> 0 | J3: =Owen!L3 -> 0 | K3: =Reddy!L3 -> 0 | L3: =Garret!L3 -> 0 | M3: =Mac!L3 -> 0 | N3: ='Noonan '!L3 -> 0
A4: =Results!B3 -> 46185 | B4: =Results!C3 -> 0.83333333 | C4: =Results!D3 -> Group B | D4: =Results!E3 -> Canada | E4: =Results!I3 -> 1-1 | F4: =Results!H3 -> Bosnia and Herzegovina | G4: =Daithi!L4 -> 1 | H4: =Kian!L4 -> 3 | I4: =Mick!L4 -> 0 | J4: =Owen!L4 -> 0 | K4: =Reddy!L4 -> 0 | L4: =Garret!L4 -> 3 | M4: =Mac!L4 -> 1 | N4: ='Noonan '!L4 -> 0
A5: =Results!B4 -> 46186 | B5: =Results!C4 -> 0.083333333 | C5: =Results!D4 -> Group D | D5: =Results!E4 -> USA | E5: =Results!I4 -> 4-1 | F5: =Results!H4 -> Paraguay | G5: =Daithi!L5 -> 1 | H5: =Kian!L5 -> 0 | I5: =Mick!L5 -> 1 | J5: =Owen!L5 -> 0 | K5: =Reddy!L5 -> 1 | L5: =Garret!L5 -> 0 | M5: =Mac!L5 -> 1 | N5: ='Noonan '!L5 -> 1
A6: =Results!B5 -> 46186 | B6: =Results!C5 -> 0.83333333 | C6: =Results!D5 -> Group B | D6: =Results!E5 -> Qatar | E6: =Results!I5 -> 1-1 | F6: =Results!H5 -> Switzerland | G6: =Daithi!L6 -> 0 | H6: =Kian!L6 -> 0 | I6: =Mick!L6 -> 0 | J6: =Owen!L6 -> 0 | K6: =Reddy!L6 -> 0 | L6: =Garret!L6 -> 0 | M6: =Mac!L6 -> 0 | N6: ='Noonan '!L6 -> 0
A7: =Results!B6 -> 46186 | B7: =Results!C6 -> 0.95833333 | C7: =Results!D6 -> Group C | D7: =Results!E6 -> Brazil | E7: =Results!I6 -> 1-1 | F7: =Results!H6 -> Morocco | G7: =Daithi!L7 -> 0 | H7: =Kian!L7 -> 3 | I7: =Mick!L7 -> 0 | J7: =Owen!L7 -> 0 | K7: =Reddy!L7 -> 0 | L7: =Garret!L7 -> 0 | M7: =Mac!L7 -> 0 | N7: ='Noonan '!L7 -> 3
A8: =Results!B7 -> 46187 | B8: =Results!C7 -> 0.083333333 | C8: =Results!D7 -> Group C | D8: =Results!E7 -> Haiti | E8: =Results!I7 -> 0-1 | F8: =Results!H7 -> Scotland | G8: =Daithi!L8 -> 1 | H8: =Kian!L8 -> 1 | I8: =Mick!L8 -> 1 | J8: =Owen!L8 -> 1 | K8: =Reddy!L8 -> 1 | L8: =Garret!L8 -> 1 | M8: =Mac!L8 -> 1 | N8: ='Noonan '!L8 -> 1
A9: =Results!B8 -> 46187 | B9: =Results!C8 -> 0.20833333 | C9: =Results!D8 -> Group D | D9: =Results!E8 -> Australia | E9: =Results!I8 -> 2-0 | F9: =Results!H8 -> Türkiye | G9: =Daithi!L9 -> 0 | H9: =Kian!L9 -> 0 | I9: =Mick!L9 -> 0 | J9: =Owen!L9 -> 0 | K9: =Reddy!L9 -> 0 | L9: =Garret!L9 -> 0 | M9: =Mac!L9 -> 0 | N9: ='Noonan '!L9 -> 0
A10: =Results!B9 -> 46187 | B10: =Results!C9 -> 0.75 | C10: =Results!D9 -> Group E | D10: =Results!E9 -> Germany | E10: =Results!I9 -> 7-1 | F10: =Results!H9 -> Curaçao | G10: =Daithi!L10 -> 1 | H10: =Kian!L10 -> 1 | I10: =Mick!L10 -> 1 | J10: =Owen!L10 -> 1 | K10: =Reddy!L10 -> 1 | L10: =Garret!L10 -> 1 | M10: =Mac!L10 -> 1 | N10: ='Noonan '!L10 -> 1
A11: =Results!B10 -> 46187 | B11: =Results!C10 -> 0.875 | C11: =Results!D10 -> Group F | D11: =Results!E10 -> Netherlands | E11: =Results!I10 -> 2-2 | F11: =Results!H10 -> Japan | G11: =Daithi!L11 -> 0 | H11: =Kian!L11 -> 0 | I11: =Mick!L11 -> 0 | J11: =Owen!L11 -> 0 | K11: =Reddy!L11 -> 0 | L11: =Garret!L11 -> 0 | M11: =Mac!L11 -> 1 | N11: ='Noonan '!L11 -> 1
A12: =Results!B11 -> 46188 | B12: =Results!C11 -> 0 | C12: =Results!D11 -> Group E | D12: =Results!E11 -> Ivory Coast | E12: =Results!I11 -> 1-0 | F12: =Results!H11 -> Ecuador | G12: =Daithi!L12 -> 0 | H12: =Kian!L12 -> 0 | I12: =Mick!L12 -> 0 | J12: =Owen!L12 -> 1 | K12: =Reddy!L12 -> 0 | L12: =Garret!L12 -> 0 | M12: =Mac!L12 -> 0 | N12: ='Noonan '!L12 -> 3
A13: =Results!B12 -> 46188 | B13: =Results!C12 -> 0.125 | C13: =Results!D12 -> Group F | D13: =Results!E12 -> Sweden | E13: =Results!I12 -> 5-1 | F13: =Results!H12 -> Tunisia | G13: =Daithi!L13 -> 1 | H13: =Kian!L13 -> 1 | I13: =Mick!L13 -> 1 | J13: =Owen!L13 -> 1 | K13: =Reddy!L13 -> 1 | L13: =Garret!L13 -> 0 | M13: =Mac!L13 -> 0 | N13: ='Noonan '!L13 -> 1
... A105: =Results!B104 -> 46222 | B105: =Results!C104 -> 0.83333333 | C105: =Results!D104 -> Final | D105: =Results!E104 -> Winner Match 101 | E105: =Results!I104 -> - | F105: =Results!H104 -> Winner Match 102 | G105: =Daithi!L105 -> 0 | H105: =Kian!L105 -> 0 | I105: =Mick!L105 -> 0 | J105: =Owen!L105 -> 0 | K105: =Reddy!L105 -> 0 | L105: =Garret!L105 -> 0 | M105: =Mac!L105 -> 0 | N105: ='Noonan '!L105 -> 0

Sheet Daithi
A2: =Results!A1 -> 5 | B2: =Results!B1 -> 46184 | C2: =Results!C1 -> 0.83333333 | D2: =Results!E1 -> Mexico | E2: 2 | F2: 0 | G2: =Results!H1 -> South Africa | H2: =E2-F2 -> 2 | I2: =if(Results!I1="-",0,IF(OR(AND(H2>0,Results!J1>0),AND(H2<0,Results!J1<0),AND(H2=0,Results!J1=0)),1,0)) -> 1 | J2: =IF(K2="-",0,if(K2=Results!I1,3,0)) -> 3 | K2: =E2&"-"&F2 -> 2-0 | L2: =MAX(I2,J2) -> 3
A3: =Results!A2 -> 6 | B3: =Results!B2 -> 46185 | C3: =Results!C2 -> 0.125 | D3: =Results!E2 -> South Korea | E3: 0 | F3: 2 | G3: =Results!H2 -> Czech Republic | H3: =E3-F3 -> -2 | I3: =if(Results!I2="-",0,IF(OR(AND(H3>0,Results!J2>0),AND(H3<0,Results!J2<0),AND(H3=0,Results!J2=0)),1,0)) -> 0 | J3: =IF(K3="-",0,if(K3=Results!I2,3,0)) -> 0 | K3: =E3&"-"&F3 -> 0-2 | L3: =MAX(I3,J3) -> 0
A4: =Results!A3 -> 6 | B4: =Results!B3 -> 46185 | C4: =Results!C3 -> 0.83333333 | D4: =Results!E3 -> Canada | E4: 0 | F4: 0 | G4: =Results!H3 -> Bosnia and Herzegovina | H4: =E4-F4 -> 0 | I4: =if(Results!I3="-",0,IF(OR(AND(H4>0,Results!J3>0),AND(H4<0,Results!J3<0),AND(H4=0,Results!J3=0)),1,0)) -> 1 | J4: =IF(K4="-",0,if(K4=Results!I3,3,0)) -> 0 | K4: =E4&"-"&F4 -> 0-0 | L4: =MAX(I4,J4) -> 1
A5: =Results!A4 -> 7 | B5: =Results!B4 -> 46186 | C5: =Results!C4 -> 0.083333333 | D5: =Results!E4 -> USA | E5: 1 | F5: 0 | G5: =Results!H4 -> Paraguay | H5: =E5-F5 -> 1 | I5: =if(Results!I4="-",0,IF(OR(AND(H5>0,Results!J4>0),AND(H5<0,Results!J4<0),AND(H5=0,Results!J4=0)),1,0)) -> 1 | J5: =IF(K5="-",0,if(K5=Results!I4,3,0)) -> 0 | K5: =E5&"-"&F5 -> 1-0 | L5: =MAX(I5,J5) -> 1
A6: =Results!A5 -> 7 | B6: =Results!B5 -> 46186 | C6: =Results!C5 -> 0.83333333 | D6: =Results!E5 -> Qatar | E6: 0 | F6: 3 | G6: =Results!H5 -> Switzerland | H6: =E6-F6 -> -3 | I6: =if(Results!I5="-",0,IF(OR(AND(H6>0,Results!J5>0),AND(H6<0,Results!J5<0),AND(H6=0,Results!J5=0)),1,0)) -> 0 | J6: =IF(K6="-",0,if(K6=Results!I5,3,0)) -> 0 | K6: =E6&"-"&F6 -> 0-3 | L6: =MAX(I6,J6) -> 0
A7: =Results!A6 -> 7 | B7: =Results!B6 -> 46186 | C7: =Results!C6 -> 0.95833333 | D7: =Results!E6 -> Brazil | E7: 3 | F7: 1 | G7: =Results!H6 -> Morocco | H7: =E7-F7 -> 2 | I7: =if(Results!I6="-",0,IF(OR(AND(H7>0,Results!J6>0),AND(H7<0,Results!J6<0),AND(H7=0,Results!J6=0)),1,0)) -> 0 | J7: =IF(K7="-",0,if(K7=Results!I6,3,0)) -> 0 | K7: =E7&"-"&F7 -> 3-1 | L7: =MAX(I7,J7) -> 0
A8: =Results!A7 -> 1 | B8: =Results!B7 -> 46187 | C8: =Results!C7 -> 0.083333333 | D8: =Results!E7 -> Haiti | E8: 0 | F8: 2 | G8: =Results!H7 -> Scotland | H8: =E8-F8 -> -2 | I8: =if(Results!I7="-",0,IF(OR(AND(H8>0,Results!J7>0),AND(H8<0,Results!J7<0),AND(H8=0,Results!J7=0)),1,0)) -> 1 | J8: =IF(K8="-",0,if(K8=Results!I7,3,0)) -> 0 | K8: =E8&"-"&F8 -> 0-2 | L8: =MAX(I8,J8) -> 1
A9: =Results!A8 -> 1 | B9: =Results!B8 -> 46187 | C9: =Results!C8 -> 0.20833333 | D9: =Results!E8 -> Australia | E9: 1 | F9: 1 | G9: =Results!H8 -> Türkiye | H9: =E9-F9 -> 0 | I9: =if(Results!I8="-",0,IF(OR(AND(H9>0,Results!J8>0),AND(H9<0,Results!J8<0),AND(H9=0,Results!J8=0)),1,0)) -> 0 | J9: =IF(K9="-",0,if(K9=Results!I8,3,0)) -> 0 | K9: =E9&"-"&F9 -> 1-1 | L9: =MAX(I9,J9) -> 0
A10: =Results!A9 -> 1 | B10: =Results!B9 -> 46187 | C10: =Results!C9 -> 0.75 | D10: =Results!E9 -> Germany | E10: 2 | F10: 0 | G10: =Results!H9 -> Curaçao | H10: =E10-F10 -> 2 | I10: =if(Results!I9="-",0,IF(OR(AND(H10>0,Results!J9>0),AND(H10<0,Results!J9<0),AND(H10=0,Results!J9=0)),1,0)) -> 1 | J10: =IF(K10="-",0,if(K10=Results!I9,3,0)) -> 0 | K10: =E10&"-"&F10 -> 2-0 | L10: =MAX(I10,J10) -> 1
A11: =Results!A10 -> 1 | B11: =Results!B10 -> 46187 | C11: =Results!C10 -> 0.875 | D11: =Results!E10 -> Netherlands | E11: 2 | F11: 1 | G11: =Results!H10 -> Japan | H11: =E11-F11 -> 1 | I11: =if(Results!I10="-",0,IF(OR(AND(H11>0,Results!J10>0),AND(H11<0,Results!J10<0),AND(H11=0,Results!J10=0)),1,0)) -> 0 | J11: =IF(K11="-",0,if(K11=Results!I10,3,0)) -> 0 | K11: =E11&"-"&F11 -> 2-1 | L11: =MAX(I11,J11) -> 0
A12: =Results!A11 -> 2 | B12: =Results!B11 -> 46188 | C12: =Results!C11 -> 0 | D12: =Results!E11 -> Ivory Coast | E12: 1 | F12: 1 | G12: =Results!H11 -> Ecuador | H12: =E12-F12 -> 0 | I12: =if(Results!I11="-",0,IF(OR(AND(H12>0,Results!J11>0),AND(H12<0,Results!J11<0),AND(H12=0,Results!J11=0)),1,0)) -> 0 | J12: =IF(K12="-",0,if(K12=Results!I11,3,0)) -> 0 | K12: =E12&"-"&F12 -> 1-1 | L12: =MAX(I12,J12) -> 0
A13: =Results!A12 -> 2 | B13: =Results!B12 -> 46188 | C13: =Results!C12 -> 0.125 | D13: =Results!E12 -> Sweden | E13: 2 | F13: 1 | G13: =Results!H12 -> Tunisia | H13: =E13-F13 -> 1 | I13: =if(Results!I12="-",0,IF(OR(AND(H13>0,Results!J12>0),AND(H13<0,Results!J12<0),AND(H13=0,Results!J12=0)),1,0)) -> 1 | J13: =IF(K13="-",0,if(K13=Results!I12,3,0)) -> 0 | K13: =E13&"-"&F13 -> 2-1 | L13: =MAX(I13,J13) -> 1
... A36: =Results!A35 -> 1 | B36: =Results!B35 -> 46194 | C36: =Results!C35 -> 0.041666667 | D36: =Results!E35 -> Ecuador | E36: 2 | F36: 0 | G36: =Results!H35 -> Curaçao | H36: =E36-F36 -> 2 | I36: =if(Results!I35="-",0,IF(OR(AND(H36>0,Results!J35>0),AND(H36<0,Results!J35<0),AND(H36=0,Results!J35=0)),1,0)) -> 0 | J36: =IF(K36="-",0,if(K36=Results!I35,3,0)) -> 0 | K36: =E36&"-"&F36 -> 2-0 | L36: =MAX(I36,J36) -> 0
A37: =Results!A36 -> 1 | B37: =Results!B36 -> 46194 | C37: =Results!C36 -> 0.20833333 | D37: =Results!E36 -> Tunisia | F37: 3 | G37: =Results!H36 -> Japan | H37: =E37-F37 -> -3 | I37: =if(Results!I36="-",0,IF(OR(AND(H37>0,Results!J36>0),AND(H37<0,Results!J36<0),AND(H37=0,Results!J36=0)),1,0)) -> 0 | J37: =IF(K37="-",0,if(K37=Results!I36,3,0)) -> 0 | K37: =E37&"-"&F37 -> -3 | L37: =MAX(I37,J37) -> 0
A38: =Results!A37 -> 1 | B38: =Results!B37 -> 46194 | C38: =Results!C37 -> 0.70833333 | D38: =Results!E37 -> Spain | G38: =Results!H37 -> Saudi Arabia | H38: =E38-F38 -> 0 | I38: =if(Results!I37="-",0,IF(OR(AND(H38>0,Results!J37>0),AND(H38<0,Results!J37<0),AND(H38=0,Results!J37=0)),1,0)) -> 0 | J38: =IF(K38="-",0,if(K38=Results!I37,3,0)) -> 0 | K38: =E38&"-"&F38 -> - | L38: =MAX(I38,J38) -> 0
A39: =Results!A38 -> 1 | B39: =Results!B38 -> 46194 | C39: =Results!C38 -> 0.83333333 | D39: =Results!E38 -> Belgium | G39: =Results!H38 -> Iran | H39: =E39-F39 -> 0 | I39: =if(Results!I38="-",0,IF(OR(AND(H39>0,Results!J38>0),AND(H39<0,Results!J38<0),AND(H39=0,Results!J38=0)),1,0)) -> 0 | J39: =IF(K39="-",0,if(K39=Results!I38,3,0)) -> 0 | K39: =E39&"-"&F39 -> - | L39: =MAX(I39,J39) -> 0
A40: =Results!A39 -> 1 | B40: =Results!B39 -> 46194 | C40: =Results!C39 -> 0.95833333 | D40: =Results!E39 -> Uruguay | G40: =Results!H39 -> Cape Verde | H40: =E40-F40 -> 0 | I40: =if(Results!I39="-",0,IF(OR(AND(H40>0,Results!J39>0),AND(H40<0,Results!J39<0),AND(H40=0,Results!J39=0)),1,0)) -> 0 | J40: =IF(K40="-",0,if(K40=Results!I39,3,0)) -> 0 | K40: =E40&"-"&F40 -> - | L40: =MAX(I40,J40) -> 0
A41: =Results!A40 -> 2 | B41: =Results!B40 -> 46195 | C41: =Results!C40 -> 0.083333333 | D41: =Results!E40 -> New Zealand | G41: =Results!H40 -> Egypt | H41: =E41-F41 -> 0 | I41: =if(Results!I40="-",0,IF(OR(AND(H41>0,Results!J40>0),AND(H41<0,Results!J40<0),AND(H41=0,Results!J40=0)),1,0)) -> 0 | J41: =IF(K41="-",0,if(K41=Results!I40,3,0)) -> 0 | K41: =E41&"-"&F41 -> - | L41: =MAX(I41,J41) -> 0
A42: =Results!A41 -> 2 | B42: =Results!B41 -> 46195 | C42: =Results!C41 -> 0.79166667 | D42: =Results!E41 -> Argentina | G42: =Results!H41 -> Austria | H42: =E42-F42 -> 0 | I42: =if(Results!I41="-",0,IF(OR(AND(H42>0,Results!J41>0),AND(H42<0,Results!J41<0),AND(H42=0,Results!J41=0)),1,0)) -> 0 | J42: =IF(K42="-",0,if(K42=Results!I41,3,0)) -> 0 | K42: =E42&"-"&F42 -> - | L42: =MAX(I42,J42) -> 0
A43: =Results!A42 -> 2 | B43: =Results!B42 -> 46195 | C43: =Results!C42 -> 0.95833333 | D43: =Results!E42 -> France | G43: =Results!H42 -> Iraq | H43: =E43-F43 -> 0 | I43: =if(Results!I42="-",0,IF(OR(AND(H43>0,Results!J42>0),AND(H43<0,Results!J42<0),AND(H43=0,Results!J42=0)),1,0)) -> 0 | J43: =IF(K43="-",0,if(K43=Results!I42,3,0)) -> 0 | K43: =E43&"-"&F43 -> - | L43: =MAX(I43,J43) -> 0
A44: =Results!A43 -> 3 | B44: =Results!B43 -> 46196 | C44: =Results!C43 -> 0.083333333 | D44: =Results!E43 -> Norway | G44: =Results!H43 -> Senegal | H44: =E44-F44 -> 0 | I44: =if(Results!I43="-",0,IF(OR(AND(H44>0,Results!J43>0),AND(H44<0,Results!J43<0),AND(H44=0,Results!J43=0)),1,0)) -> 0 | J44: =IF(K44="-",0,if(K44=Results!I43,3,0)) -> 0 | K44: =E44&"-"&F44 -> - | L44: =MAX(I44,J44) -> 0
A45: =Results!A44 -> 3 | B45: =Results!B44 -> 46196 | C45: =Results!C44 -> 0.20833333 | D45: =Results!E44 -> Jordan | G45: =Results!H44 -> Algeria | H45: =E45-F45 -> 0 | I45: =if(Results!I44="-",0,IF(OR(AND(H45>0,Results!J44>0),AND(H45<0,Results!J44<0),AND(H45=0,Results!J44=0)),1,0)) -> 0 | J45: =IF(K45="-",0,if(K45=Results!I44,3,0)) -> 0 | K45: =E45&"-"&F45 -> - | L45: =MAX(I45,J45) -> 0
A46: =Results!A45 -> 3 | B46: =Results!B45 -> 46196 | C46: =Results!C45 -> 0.79166667 | D46: =Results!E45 -> Portugal | G46: =Results!H45 -> Uzbekistan | H46: =E46-F46 -> 0 | I46: =if(Results!I45="-",0,IF(OR(AND(H46>0,Results!J45>0),AND(H46<0,Results!J45<0),AND(H46=0,Results!J45=0)),1,0)) -> 0 | J46: =IF(K46="-",0,if(K46=Results!I45,3,0)) -> 0 | K46: =E46&"-"&F46 -> - | L46: =MAX(I46,J46) -> 0
A47: =Results!A46 -> 3 | B47: =Results!B46 -> 46196 | C47: =Results!C46 -> 0.91666667 | D47: =Results!E46 -> England | G47: =Results!H46 -> Ghana | H47: =E47-F47 -> 0 | I47: =if(Results!I46="-",0,IF(OR(AND(H47>0,Results!J46>0),AND(H47<0,Results!J46<0),AND(H47=0,Results!J46=0)),1,0)) -> 0 | J47: =IF(K47="-",0,if(K47=Results!I46,3,0)) -> 0 | K47: =E47&"-"&F47 -> - | L47: =MAX(I47,J47) -> 0
A48: =Results!A47 -> 4 | B48: =Results!B47 -> 46197 | C48: =Results!C47 -> 0.041666667 | D48: =Results!E47 -> Panama | G48: =Results!H47 -> Croatia | H48: =E48-F48 -> 0 | I48: =if(Results!I47="-",0,IF(OR(AND(H48>0,Results!J47>0),AND(H48<0,Results!J47<0),AND(H48=0,Results!J47=0)),1,0)) -> 0 | J48: =IF(K48="-",0,if(K48=Results!I47,3,0)) -> 0 | K48: =E48&"-"&F48 -> - | L48: =MAX(I48,J48) -> 0
A49: =Results!A48 -> 4 | B49: =Results!B48 -> 46197 | C49: =Results!C48 -> 0.16666667 | D49: =Results!E48 -> Colombia | G49: =Results!H48 -> DR Congo | H49: =E49-F49 -> 0 | I49: =if(Results!I48="-",0,IF(OR(AND(H49>0,Results!J48>0),AND(H49<0,Results!J48<0),AND(H49=0,Results!J48=0)),1,0)) -> 0 | J49: =IF(K49="-",0,if(K49=Results!I48,3,0)) -> 0 | K49: =E49&"-"&F49 -> - | L49: =MAX(I49,J49) -> 0
... A105: =Results!A104 -> 1 | B105: =Results!B104 -> 46222 | C105: =Results!C104 -> 0.83333333 | D105: =Results!E104 -> Winner Match 101 | G105: =Results!H104 -> Winner Match 102 | H105: =E105-F105 -> 0 | I105: =if(Results!I104="-",0,IF(OR(AND(H105>0,Results!J104>0),AND(H105<0,Results!J104<0),AND(H105=0,Results!J104=0)),1,0)) -> 0 | J105: =IF(K105="-",0,if(K105=Results!I104,3,0)) -> 0 | K105: =E105&"-"&F105 -> - | L105: =MAX(I105,J105) -> 0

Sheet Kian
A2: =Results!A1 -> 5 | B2: =Results!B1 -> 46184 | C2: =Results!C1 -> 0.83333333 | D2: =Results!E1 -> Mexico | E2: 2 | F2: 1 | G2: =Results!H1 -> South Africa | H2: =E2-F2 -> 1 | I2: =if(Results!I1="-",0,IF(OR(AND(H2>0,Results!J1>0),AND(H2<0,Results!J1<0),AND(H2=0,Results!J1=0)),1,0)) -> 1 | J2: =IF(K2="-",0,if(K2=Results!I1,3,0)) -> 0 | K2: =E2&"-"&F2 -> 2-1 | L2: =MAX(I2,J2) -> 1
A3: =Results!A2 -> 6 | B3: =Results!B2 -> 46185 | C3: =Results!C2 -> 0.125 | D3: =Results!E2 -> South Korea | E3: 1 | F3: 0 | G3: =Results!H2 -> Czech Republic | H3: =E3-F3 -> 1 | I3: =if(Results!I2="-",0,IF(OR(AND(H3>0,Results!J2>0),AND(H3<0,Results!J2<0),AND(H3=0,Results!J2=0)),1,0)) -> 1 | J3: =IF(K3="-",0,if(K3=Results!I2,3,0)) -> 0 | K3: =E3&"-"&F3 -> 1-0 | L3: =MAX(I3,J3) -> 1
A4: =Results!A3 -> 6 | B4: =Results!B3 -> 46185 | C4: =Results!C3 -> 0.83333333 | D4: =Results!E3 -> Canada | E4: 1 | F4: 1 | G4: =Results!H3 -> Bosnia and Herzegovina | H4: =E4-F4 -> 0 | I4: =if(Results!I3="-",0,IF(OR(AND(H4>0,Results!J3>0),AND(H4<0,Results!J3<0),AND(H4=0,Results!J3=0)),1,0)) -> 1 | J4: =IF(K4="-",0,if(K4=Results!I3,3,0)) -> 3 | K4: =E4&"-"&F4 -> 1-1 | L4: =MAX(I4,J4) -> 3
A5: =Results!A4 -> 7 | B5: =Results!B4 -> 46186 | C5: =Results!C4 -> 0.083333333 | D5: =Results!E4 -> USA | G5: =Results!H4 -> Paraguay | H5: =E5-F5 -> 0 | I5: =if(Results!I4="-",0,IF(OR(AND(H5>0,Results!J4>0),AND(H5<0,Results!J4<0),AND(H5=0,Results!J4=0)),1,0)) -> 0 | J5: =IF(K5="-",0,if(K5=Results!I4,3,0)) -> 0 | K5: =E5&"-"&F5 -> - | L5: =MAX(I5,J5) -> 0
A6: =Results!A5 -> 7 | B6: =Results!B5 -> 46186 | C6: =Results!C5 -> 0.83333333 | D6: =Results!E5 -> Qatar | E6: 0 | F6: 2 | G6: =Results!H5 -> Switzerland | H6: =E6-F6 -> -2 | I6: =if(Results!I5="-",0,IF(OR(AND(H6>0,Results!J5>0),AND(H6<0,Results!J5<0),AND(H6=0,Results!J5=0)),1,0)) -> 0 | J6: =IF(K6="-",0,if(K6=Results!I5,3,0)) -> 0 | K6: =E6&"-"&F6 -> 0-2 | L6: =MAX(I6,J6) -> 0
A7: =Results!A6 -> 7 | B7: =Results!B6 -> 46186 | C7: =Results!C6 -> 0.95833333 | D7: =Results!E6 -> Brazil | E7: 1 | F7: 1 | G7: =Results!H6 -> Morocco | H7: =E7-F7 -> 0 | I7: =if(Results!I6="-",0,IF(OR(AND(H7>0,Results!J6>0),AND(H7<0,Results!J6<0),AND(H7=0,Results!J6=0)),1,0)) -> 1 | J7: =IF(K7="-",0,if(K7=Results!I6,3,0)) -> 3 | K7: =E7&"-"&F7 -> 1-1 | L7: =MAX(I7,J7) -> 3
A8: =Results!A7 -> 1 | B8: =Results!B7 -> 46187 | C8: =Results!C7 -> 0.083333333 | D8: =Results!E7 -> Haiti | E8: 0 | F8: 3 | G8: =Results!H7 -> Scotland | H8: =E8-F8 -> -3 | I8: =if(Results!I7="-",0,IF(OR(AND(H8>0,Results!J7>0),AND(H8<0,Results!J7<0),AND(H8=0,Results!J7=0)),1,0)) -> 1 | J8: =IF(K8="-",0,if(K8=Results!I7,3,0)) -> 0 | K8: =E8&"-"&F8 -> 0-3 | L8: =MAX(I8,J8) -> 1
A9: =Results!A8 -> 1 | B9: =Results!B8 -> 46187 | C9: =Results!C8 -> 0.20833333 | D9: =Results!E8 -> Australia | G9: =Results!H8 -> Türkiye | H9: =E9-F9 -> 0 | I9: =if(Results!I8="-",0,IF(OR(AND(H9>0,Results!J8>0),AND(H9<0,Results!J8<0),AND(H9=0,Results!J8=0)),1,0)) -> 0 | J9: =IF(K9="-",0,if(K9=Results!I8,3,0)) -> 0 | K9: =E9&"-"&F9 -> - | L9: =MAX(I9,J9) -> 0
A10: =Results!A9 -> 1 | B10: =Results!B9 -> 46187 | C10: =Results!C9 -> 0.75 | D10: =Results!E9 -> Germany | E10: 5 | F10: 0 | G10: =Results!H9 -> Curaçao | H10: =E10-F10 -> 5 | I10: =if(Results!I9="-",0,IF(OR(AND(H10>0,Results!J9>0),AND(H10<0,Results!J9<0),AND(H10=0,Results!J9=0)),1,0)) -> 1 | J10: =IF(K10="-",0,if(K10=Results!I9,3,0)) -> 0 | K10: =E10&"-"&F10 -> 5-0 | L10: =MAX(I10,J10) -> 1
A11: =Results!A10 -> 1 | B11: =Results!B10 -> 46187 | C11: =Results!C10 -> 0.875 | D11: =Results!E10 -> Netherlands | E11: 2 | F11: 1 | G11: =Results!H10 -> Japan | H11: =E11-F11 -> 1 | I11: =if(Results!I10="-",0,IF(OR(AND(H11>0,Results!J10>0),AND(H11<0,Results!J10<0),AND(H11=0,Results!J10=0)),1,0)) -> 0 | J11: =IF(K11="-",0,if(K11=Results!I10,3,0)) -> 0 | K11: =E11&"-"&F11 -> 2-1 | L11: =MAX(I11,J11) -> 0
A12: =Results!A11 -> 2 | B12: =Results!B11 -> 46188 | C12: =Results!C11 -> 0 | D12: =Results!E11 -> Ivory Coast | E12: 1 | F12: 1 | G12: =Results!H11 -> Ecuador | H12: =E12-F12 -> 0 | I12: =if(Results!I11="-",0,IF(OR(AND(H12>0,Results!J11>0),AND(H12<0,Results!J11<0),AND(H12=0,Results!J11=0)),1,0)) -> 0 | J12: =IF(K12="-",0,if(K12=Results!I11,3,0)) -> 0 | K12: =E12&"-"&F12 -> 1-1 | L12: =MAX(I12,J12) -> 0
A13: =Results!A12 -> 2 | B13: =Results!B12 -> 46188 | C13: =Results!C12 -> 0.125 | D13: =Results!E12 -> Sweden | E13: 2 | F13: 0 | G13: =Results!H12 -> Tunisia | H13: =E13-F13 -> 2 | I13: =if(Results!I12="-",0,IF(OR(AND(H13>0,Results!J12>0),AND(H13<0,Results!J12<0),AND(H13=0,Results!J12=0)),1,0)) -> 1 | J13: =IF(K13="-",0,if(K13=Results!I12,3,0)) -> 0 | K13: =E13&"-"&F13 -> 2-0 | L13: =MAX(I13,J13) -> 1
A14: =Results!A13 -> 2 | B14: =Results!B13 -> 46188 | C14: =Results!C13 -> 0.70833333 | D14: =Results!E13 -> Spain | E14: 2 | F14: 0 | G14: =Results!H13 -> Cape Verde | H14: =E14-F14 -> 2 | I14: =if(Results!I13="-",0,IF(OR(AND(H14>0,Results!J13>0),AND(H14<0,Results!J13<0),AND(H14=0,Results!J13=0)),1,0)) -> 0 | J14: =IF(K14="-",0,if(K14=Results!I13,3,0)) -> 0 | K14: =E14&"-"&F14 -> 2-0 | L14: =MAX(I14,J14) -> 0
A15: =Results!A14 -> 2 | B15: =Results!B14 -> 46188 | C15: =Results!C14 -> 0.83333333 | D15: =Results!E14 -> Belgium | E15: 2 | F15: 1 | G15: =Results!H14 -> Egypt | H15: =E15-F15 -> 1 | I15: =if(Results!I14="-",0,IF(OR(AND(H15>0,Results!J14>0),AND(H15<0,Results!J14<0),AND(H15=0,Results!J14=0)),1,0)) -> 0 | J15: =IF(K15="-",0,if(K15=Results!I14,3,0)) -> 0 | K15: =E15&"-"&F15 -> 2-1 | L15: =MAX(I15,J15) -> 0
A16: =Results!A15 -> 2 | B16: =Results!B15 -> 46188 | C16: =Results!C15 -> 0.95833333 | D16: =Results!E15 -> Saudi Arabia | E16: 1 | F16: 2 | G16: =Results!H15 -> Uruguay | H16: =E16-F16 -> -1 | I16: =if(Results!I15="-",0,IF(OR(AND(H16>0,Results!J15>0),AND(H16<0,Results!J15<0),AND(H16=0,Results!J15=0)),1,0)) -> 0 | J16: =IF(K16="-",0,if(K16=Results!I15,3,0)) -> 0 | K16: =E16&"-"&F16 -> 1-2 | L16: =MAX(I16,J16) -> 0
A17: =Results!A16 -> 3 | B17: =Results!B16 -> 46189 | C17: =Results!C16 -> 0.083333333 | D17: =Results!E16 -> Iran | E17: 3 | F17: 0 | G17: =Results!H16 -> New Zealand | H17: =E17-F17 -> 3 | I17: =if(Results!I16="-",0,IF(OR(AND(H17>0,Results!J16>0),AND(H17<0,Results!J16<0),AND(H17=0,Results!J16=0)),1,0)) -> 0 | J17: =IF(K17="-",0,if(K17=Results!I16,3,0)) -> 0 | K17: =E17&"-"&F17 -> 3-0 | L17: =MAX(I17,J17) -> 0
A18: =Results!A17 -> 3 | B18: =Results!B17 -> 46189 | C18: =Results!C17 -> 0.83333333 | D18: =Results!E17 -> France | E18: 2 | F18: 2 | G18: =Results!H17 -> Senegal | H18: =E18-F18 -> 0 | I18: =if(Results!I17="-",0,IF(OR(AND(H18>0,Results!J17>0),AND(H18<0,Results!J17<0),AND(H18=0,Results!J17=0)),1,0)) -> 0 | J18: =IF(K18="-",0,if(K18=Results!I17,3,0)) -> 0 | K18: =E18&"-"&F18 -> 2-2 | L18: =MAX(I18,J18) -> 0
A19: =Results!A18 -> 3 | B19: =Results!B18 -> 46189 | C19: =Results!C18 -> 0.95833333 | D19: =Results!E18 -> Iraq | E19: 0 | F19: 4 | G19: =Results!H18 -> Norway | H19: =E19-F19 -> -4 | I19: =if(Results!I18="-",0,IF(OR(AND(H19>0,Results!J18>0),AND(H19<0,Results!J18<0),AND(H19=0,Results!J18=0)),1,0)) -> 1 | J19: =IF(K19="-",0,if(K19=Results!I18,3,0)) -> 0 | K19: =E19&"-"&F19 -> 0-4 | L19: =MAX(I19,J19) -> 1
A20: =Results!A19 -> 4 | B20: =Results!B19 -> 46190 | C20: =Results!C19 -> 0.083333333 | D20: =Results!E19 -> Argentina | E20: 2 | F20: 1 | G20: =Results!H19 -> Algeria | H20: =E20-F20 -> 1 | I20: =if(Results!I19="-",0,IF(OR(AND(H20>0,Results!J19>0),AND(H20<0,Results!J19<0),AND(H20=0,Results!J19=0)),1,0)) -> 1 | J20: =IF(K20="-",0,if(K20=Results!I19,3,0)) -> 0 | K20: =E20&"-"&F20 -> 2-1 | L20: =MAX(I20,J20) -> 1
A21: =Results!A20 -> 4 | B21: =Results!B20 -> 46190 | C21: =Results!C20 -> 0.20833333 | D21: =Results!E20 -> Austria | E21: 2 | F21: 0 | G21: =Results!H20 -> Jordan | H21: =E21-F21 -> 2 | I21: =if(Results!I20="-",0,IF(OR(AND(H21>0,Results!J20>0),AND(H21<0,Results!J20<0),AND(H21=0,Results!J20=0)),1,0)) -> 1 | J21: =IF(K21="-",0,if(K21=Results!I20,3,0)) -> 0 | K21: =E21&"-"&F21 -> 2-0 | L21: =MAX(I21,J21) -> 1
... A25: =Results!A24 -> 5 | B25: =Results!B24 -> 46191 | C25: =Results!C24 -> 0.125 | D25: =Results!E24 -> Uzbekistan | E25: 1 | F25: 1 | G25: =Results!H24 -> Colombia | H25: =E25-F25 -> 0 | I25: =if(Results!I24="-",0,IF(OR(AND(H25>0,Results!J24>0),AND(H25<0,Results!J24<0),AND(H25=0,Results!J24=0)),1,0)) -> 0 | J25: =IF(K25="-",0,if(K25=Results!I24,3,0)) -> 0 | K25: =E25&"-"&F25 -> 1-1 | L25: =MAX(I25,J25) -> 0
A26: =Results!A25 -> 5 | B26: =Results!B25 -> 46191 | C26: =Results!C25 -> 0.70833333 | D26: =Results!E25 -> Czechia | G26: =Results!H25 -> South Africa | H26: =E26-F26 -> 0 | I26: =if(Results!I25="-",0,IF(OR(AND(H26>0,Results!J25>0),AND(H26<0,Results!J25<0),AND(H26=0,Results!J25=0)),1,0)) -> 1 | J26: =IF(K26="-",0,if(K26=Results!I25,3,0)) -> 0 | K26: =E26&"-"&F26 -> - | L26: =MAX(I26,J26) -> 1
A27: =Results!A26 -> 5 | B27: =Results!B26 -> 46191 | C27: =Results!C26 -> 0.83333333 | D27: =Results!E26 -> Switzerland | E27: 2 | F27: 0 | G27: =Results!H26 -> Bosnia and Herzegovina | H27: =E27-F27 -> 2 | I27: =if(Results!I26="-",0,IF(OR(AND(H27>0,Results!J26>0),AND(H27<0,Results!J26<0),AND(H27=0,Results!J26=0)),1,0)) -> 1 | J27: =IF(K27="-",0,if(K27=Results!I26,3,0)) -> 0 | K27: =E27&"-"&F27 -> 2-0 | L27: =MAX(I27,J27) -> 1
A28: =Results!A27 -> 5 | B28: =Results!B27 -> 46191 | C28: =Results!C27 -> 0.95833333 | D28: =Results!E27 -> Canada | E28: 2 | F28: 1 | G28: =Results!H27 -> Qatar | H28: =E28-F28 -> 1 | I28: =if(Results!I27="-",0,IF(OR(AND(H28>0,Results!J27>0),AND(H28<0,Results!J27<0),AND(H28=0,Results!J27=0)),1,0)) -> 1 | J28: =IF(K28="-",0,if(K28=Results!I27,3,0)) -> 0 | K28: =E28&"-"&F28 -> 2-1 | L28: =MAX(I28,J28) -> 1
A29: =Results!A28 -> 6 | B29: =Results!B28 -> 46192 | C29: =Results!C28 -> 0.083333333 | D29: =Results!E28 -> Mexico | E29: 2 | F29: 2 | G29: =Results!H28 -> South Korea | H29: =E29-F29 -> 0 | I29: =if(Results!I28="-",0,IF(OR(AND(H29>0,Results!J28>0),AND(H29<0,Results!J28<0),AND(H29=0,Results!J28=0)),1,0)) -> 0 | J29: =IF(K29="-",0,if(K29=Results!I28,3,0)) -> 0 | K29: =E29&"-"&F29 -> 2-2 | L29: =MAX(I29,J29) -> 0
A30: =Results!A29 -> 6 | B30: =Results!B29 -> 46192 | C30: =Results!C29 -> 0.83333333 | D30: =Results!E29 -> USA | E30: 2 | F30: 1 | G30: =Results!H29 -> Australia | H30: =E30-F30 -> 1 | I30: =if(Results!I29="-",0,IF(OR(AND(H30>0,Results!J29>0),AND(H30<0,Results!J29<0),AND(H30=0,Results!J29=0)),1,0)) -> 1 | J30: =IF(K30="-",0,if(K30=Results!I29,3,0)) -> 0 | K30: =E30&"-"&F30 -> 2-1 | L30: =MAX(I30,J30) -> 1
A31: =Results!A30 -> 6 | B31: =Results!B30 -> 46192 | C31: =Results!C30 -> 0.95833333 | D31: =Results!E30 -> Scotland | E31: 0 | F31: 1 | G31: =Results!H30 -> Morocco | H31: =E31-F31 -> -1 | I31: =if(Results!I30="-",0,IF(OR(AND(H31>0,Results!J30>0),AND(H31<0,Results!J30<0),AND(H31=0,Results!J30=0)),1,0)) -> 1 | J31: =IF(K31="-",0,if(K31=Results!I30,3,0)) -> 3 | K31: =E31&"-"&F31 -> 0-1 | L31: =MAX(I31,J31) -> 3
A32: =Results!A31 -> 7 | B32: =Results!B31 -> 46193 | C32: =Results!C31 -> 0.0625 | D32: =Results!E31 -> Brazil | E32: 3 | F32: 0 | G32: =Results!H31 -> Haiti | H32: =E32-F32 -> 3 | I32: =if(Results!I31="-",0,IF(OR(AND(H32>0,Results!J31>0),AND(H32<0,Results!J31<0),AND(H32=0,Results!J31=0)),1,0)) -> 1 | J32: =IF(K32="-",0,if(K32=Results!I31,3,0)) -> 3 | K32: =E32&"-"&F32 -> 3-0 | L32: =MAX(I32,J32) -> 3
A33: =Results!A32 -> 7 | B33: =Results!B32 -> 46193 | C33: =Results!C32 -> 0.16666667 | D33: =Results!E32 -> Turkey | E33: 2 | F33: 1 | G33: =Results!H32 -> Paraguay | H33: =E33-F33 -> 1 | I33: =if(Results!I32="-",0,IF(OR(AND(H33>0,Results!J32>0),AND(H33<0,Results!J32<0),AND(H33=0,Results!J32=0)),1,0)) -> 0 | J33: =IF(K33="-",0,if(K33=Results!I32,3,0)) -> 0 | K33: =E33&"-"&F33 -> 2-1 | L33: =MAX(I33,J33) -> 0
A34: =Results!A33 -> 7 | B34: =Results!B33 -> 46193 | C34: =Results!C33 -> 0.75 | D34: =Results!E33 -> Netherlands | G34: =Results!H33 -> Sweden | H34: =E34-F34 -> 0 | I34: =if(Results!I33="-",0,IF(OR(AND(H34>0,Results!J33>0),AND(H34<0,Results!J33<0),AND(H34=0,Results!J33=0)),1,0)) -> 0 | J34: =IF(K34="-",0,if(K34=Results!I33,3,0)) -> 0 | K34: =E34&"-"&F34 -> - | L34: =MAX(I34,J34) -> 0
A35: =Results!A34 -> 7 | B35: =Results!B34 -> 46193 | C35: =Results!C34 -> 0.875 | D35: =Results!E34 -> Germany | G35: =Results!H34 -> Ivory Coast | H35: =E35-F35 -> 0 | I35: =if(Results!I34="-",0,IF(OR(AND(H35>0,Results!J34>0),AND(H35<0,Results!J34<0),AND(H35=0,Results!J34=0)),1,0)) -> 0 | J35: =IF(K35="-",0,if(K35=Results!I34,3,0)) -> 0 | K35: =E35&"-"&F35 -> - | L35: =MAX(I35,J35) -> 0
A36: =Results!A35 -> 1 | B36: =Results!B35 -> 46194 | C36: =Results!C35 -> 0.041666667 | D36: =Results!E35 -> Ecuador | G36: =Results!H35 -> Curaçao | H36: =E36-F36 -> 0 | I36: =if(Results!I35="-",0,IF(OR(AND(H36>0,Results!J35>0),AND(H36<0,Results!J35<0),AND(H36=0,Results!J35=0)),1,0)) -> 0 | J36: =IF(K36="-",0,if(K36=Results!I35,3,0)) -> 0 | K36: =E36&"-"&F36 -> - | L36: =MAX(I36,J36) -> 0
A37: =Results!A36 -> 1 | B37: =Results!B36 -> 46194 | C37: =Results!C36 -> 0.20833333 | D37: =Results!E36 -> Tunisia | G37: =Results!H36 -> Japan | H37: =E37-F37 -> 0 | I37: =if(Results!I36="-",0,IF(OR(AND(H37>0,Results!J36>0),AND(H37<0,Results!J36<0),AND(H37=0,Results!J36=0)),1,0)) -> 0 | J37: =IF(K37="-",0,if(K37=Results!I36,3,0)) -> 0 | K37: =E37&"-"&F37 -> - | L37: =MAX(I37,J37) -> 0
A38: =Results!A37 -> 1 | B38: =Results!B37 -> 46194 | C38: =Results!C37 -> 0.70833333 | D38: =Results!E37 -> Spain | G38: =Results!H37 -> Saudi Arabia | H38: =E38-F38 -> 0 | I38: =if(Results!I37="-",0,IF(OR(AND(H38>0,Results!J37>0),AND(H38<0,Results!J37<0),AND(H38=0,Results!J37=0)),1,0)) -> 0 | J38: =IF(K38="-",0,if(K38=Results!I37,3,0)) -> 0 | K38: =E38&"-"&F38 -> - | L38: =MAX(I38,J38) -> 0
A39: =Results!A38 -> 1 | B39: =Results!B38 -> 46194 | C39: =Results!C38 -> 0.83333333 | D39: =Results!E38 -> Belgium | G39: =Results!H38 -> Iran | H39: =E39-F39 -> 0 | I39: =if(Results!I38="-",0,IF(OR(AND(H39>0,Results!J38>0),AND(H39<0,Results!J38<0),AND(H39=0,Results!J38=0)),1,0)) -> 0 | J39: =IF(K39="-",0,if(K39=Results!I38,3,0)) -> 0 | K39: =E39&"-"&F39 -> - | L39: =MAX(I39,J39) -> 0
A40: =Results!A39 -> 1 | B40: =Results!B39 -> 46194 | C40: =Results!C39 -> 0.95833333 | D40: =Results!E39 -> Uruguay | G40: =Results!H39 -> Cape Verde | H40: =E40-F40 -> 0 | I40: =if(Results!I39="-",0,IF(OR(AND(H40>0,Results!J39>0),AND(H40<0,Results!J39<0),AND(H40=0,Results!J39=0)),1,0)) -> 0 | J40: =IF(K40="-",0,if(K40=Results!I39,3,0)) -> 0 | K40: =E40&"-"&F40 -> - | L40: =MAX(I40,J40) -> 0
A41: =Results!A40 -> 2 | B41: =Results!B40 -> 46195 | C41: =Results!C40 -> 0.083333333 | D41: =Results!E40 -> New Zealand | G41: =Results!H40 -> Egypt | H41: =E41-F41 -> 0 | I41: =if(Results!I40="-",0,IF(OR(AND(H41>0,Results!J40>0),AND(H41<0,Results!J40<0),AND(H41=0,Results!J40=0)),1,0)) -> 0 | J41: =IF(K41="-",0,if(K41=Results!I40,3,0)) -> 0 | K41: =E41&"-"&F41 -> - | L41: =MAX(I41,J41) -> 0
A42: =Results!A41 -> 2 | B42: =Results!B41 -> 46195 | C42: =Results!C41 -> 0.79166667 | D42: =Results!E41 -> Argentina | G42: =Results!H41 -> Austria | H42: =E42-F42 -> 0 | I42: =if(Results!I41="-",0,IF(OR(AND(H42>0,Results!J41>0),AND(H42<0,Results!J41<0),AND(H42=0,Results!J41=0)),1,0)) -> 0 | J42: =IF(K42="-",0,if(K42=Results!I41,3,0)) -> 0 | K42: =E42&"-"&F42 -> - | L42: =MAX(I42,J42) -> 0
A43: =Results!A42 -> 2 | B43: =Results!B42 -> 46195 | C43: =Results!C42 -> 0.95833333 | D43: =Results!E42 -> France | G43: =Results!H42 -> Iraq | H43: =E43-F43 -> 0 | I43: =if(Results!I42="-",0,IF(OR(AND(H43>0,Results!J42>0),AND(H43<0,Results!J42<0),AND(H43=0,Results!J42=0)),1,0)) -> 0 | J43: =IF(K43="-",0,if(K43=Results!I42,3,0)) -> 0 | K43: =E43&"-"&F43 -> - | L43: =MAX(I43,J43) -> 0
A44: =Results!A43 -> 3 | B44: =Results!B43 -> 46196 | C44: =Results!C43 -> 0.083333333 | D44: =Results!E43 -> Norway | G44: =Results!H43 -> Senegal | H44: =E44-F44 -> 0 | I44: =if(Results!I43="-",0,IF(OR(AND(H44>0,Results!J43>0),AND(H44<0,Results!J43<0),AND(H44=0,Results!J43=0)),1,0)) -> 0 | J44: =IF(K44="-",0,if(K44=Results!I43,3,0)) -> 0 | K44: =E44&"-"&F44 -> - | L44: =MAX(I44,J44) -> 0
...

Sheet Mick
A2: =Results!A1 -> 5 | B2: =Results!B1 -> 46184 | C2: =Results!C1 -> 0.83333333 | D2: =Results!E1 -> Mexico | E2: 2 | F2: 0 | G2: =Results!H1 -> South Africa | H2: =E2-F2 -> 2 | I2: =if(Results!I1="-",0,IF(OR(AND(H2>0,Results!J1>0),AND(H2<0,Results!J1<0),AND(H2=0,Results!J1=0)),1,0)) -> 1 | J2: =IF(K2="-",0,if(K2=Results!I1,3,0)) -> 3 | K2: =E2&"-"&F2 -> 2-0 | L2: =MAX(I2,J2) -> 3
A3: =Results!A2 -> 6 | B3: =Results!B2 -> 46185 | C3: =Results!C2 -> 0.125 | D3: =Results!E2 -> South Korea | E3: 1 | F3: 1 | G3: =Results!H2 -> Czech Republic | H3: =E3-F3 -> 0 | I3: =if(Results!I2="-",0,IF(OR(AND(H3>0,Results!J2>0),AND(H3<0,Results!J2<0),AND(H3=0,Results!J2=0)),1,0)) -> 0 | J3: =IF(K3="-",0,if(K3=Results!I2,3,0)) -> 0 | K3: =E3&"-"&F3 -> 1-1 | L3: =MAX(I3,J3) -> 0
A4: =Results!A3 -> 6 | B4: =Results!B3 -> 46185 | C4: =Results!C3 -> 0.83333333 | D4: =Results!E3 -> Canada | E4: 2 | F4: 1 | G4: =Results!H3 -> Bosnia and Herzegovina | H4: =E4-F4 -> 1 | I4: =if(Results!I3="-",0,IF(OR(AND(H4>0,Results!J3>0),AND(H4<0,Results!J3<0),AND(H4=0,Results!J3=0)),1,0)) -> 0 | J4: =IF(K4="-",0,if(K4=Results!I3,3,0)) -> 0 | K4: =E4&"-"&F4 -> 2-1 | L4: =MAX(I4,J4) -> 0
A5: =Results!A4 -> 7 | B5: =Results!B4 -> 46186 | C5: =Results!C4 -> 0.083333333 | D5: =Results!E4 -> USA | E5: 2 | F5: 0 | G5: =Results!H4 -> Paraguay | H5: =E5-F5 -> 2 | I5: =if(Results!I4="-",0,IF(OR(AND(H5>0,Results!J4>0),AND(H5<0,Results!J4<0),AND(H5=0,Results!J4=0)),1,0)) -> 1 | J5: =IF(K5="-",0,if(K5=Results!I4,3,0)) -> 0 | K5: =E5&"-"&F5 -> 2-0 | L5: =MAX(I5,J5) -> 1
A6: =Results!A5 -> 7 | B6: =Results!B5 -> 46186 | C6: =Results!C5 -> 0.83333333 | D6: =Results!E5 -> Qatar | E6: 0 | F6: 2 | G6: =Results!H5 -> Switzerland | H6: =E6-F6 -> -2 | I6: =if(Results!I5="-",0,IF(OR(AND(H6>0,Results!J5>0),AND(H6<0,Results!J5<0),AND(H6=0,Results!J5=0)),1,0)) -> 0 | J6: =IF(K6="-",0,if(K6=Results!I5,3,0)) -> 0 | K6: =E6&"-"&F6 -> 0-2 | L6: =MAX(I6,J6) -> 0
A7: =Results!A6 -> 7 | B7: =Results!B6 -> 46186 | C7: =Results!C6 -> 0.95833333 | D7: =Results!E6 -> Brazil | E7: 2 | F7: 1 | G7: =Results!H6 -> Morocco | H7: =E7-F7 -> 1 | I7: =if(Results!I6="-",0,IF(OR(AND(H7>0,Results!J6>0),AND(H7<0,Results!J6<0),AND(H7=0,Results!J6=0)),1,0)) -> 0 | J7: =IF(K7="-",0,if(K7=Results!I6,3,0)) -> 0 | K7: =E7&"-"&F7 -> 2-1 | L7: =MAX(I7,J7) -> 0
A8: =Results!A7 -> 1 | B8: =Results!B7 -> 46187 | C8: =Results!C7 -> 0.083333333 | D8: =Results!E7 -> Haiti | E8: 1 | F8: 2 | G8: =Results!H7 -> Scotland | H8: =E8-F8 -> -1 | I8: =if(Results!I7="-",0,IF(OR(AND(H8>0,Results!J7>0),AND(H8<0,Results!J7<0),AND(H8=0,Results!J7=0)),1,0)) -> 1 | J8: =IF(K8="-",0,if(K8=Results!I7,3,0)) -> 0 | K8: =E8&"-"&F8 -> 1-2 | L8: =MAX(I8,J8) -> 1
A9: =Results!A8 -> 1 | B9: =Results!B8 -> 46187 | C9: =Results!C8 -> 0.20833333 | D9: =Results!E8 -> Australia | E9: 1 | F9: 1 | G9: =Results!H8 -> Türkiye | H9: =E9-F9 -> 0 | I9: =if(Results!I8="-",0,IF(OR(AND(H9>0,Results!J8>0),AND(H9<0,Results!J8<0),AND(H9=0,Results!J8=0)),1,0)) -> 0 | J9: =IF(K9="-",0,if(K9=Results!I8,3,0)) -> 0 | K9: =E9&"-"&F9 -> 1-1 | L9: =MAX(I9,J9) -> 0
A10: =Results!A9 -> 1 | B10: =Results!B9 -> 46187 | C10: =Results!C9 -> 0.75 | D10: =Results!E9 -> Germany | E10: 3 | F10: 0 | G10: =Results!H9 -> Curaçao | H10: =E10-F10 -> 3 | I10: =if(Results!I9="-",0,IF(OR(AND(H10>0,Results!J9>0),AND(H10<0,Results!J9<0),AND(H10=0,Results!J9=0)),1,0)) -> 1 | J10: =IF(K10="-",0,if(K10=Results!I9,3,0)) -> 0 | K10: =E10&"-"&F10 -> 3-0 | L10: =MAX(I10,J10) -> 1
A11: =Results!A10 -> 1 | B11: =Results!B10 -> 46187 | C11: =Results!C10 -> 0.875 | D11: =Results!E10 -> Netherlands | E11: 2 | F11: 1 | G11: =Results!H10 -> Japan | H11: =E11-F11 -> 1 | I11: =if(Results!I10="-",0,IF(OR(AND(H11>0,Results!J10>0),AND(H11<0,Results!J10<0),AND(H11=0,Results!J10=0)),1,0)) -> 0 | J11: =IF(K11="-",0,if(K11=Results!I10,3,0)) -> 0 | K11: =E11&"-"&F11 -> 2-1 | L11: =MAX(I11,J11) -> 0
A12: =Results!A11 -> 2 | B12: =Results!B11 -> 46188 | C12: =Results!C11 -> 0 | D12: =Results!E11 -> Ivory Coast | E12: 1 | F12: 1 | G12: =Results!H11 -> Ecuador | H12: =E12-F12 -> 0 | I12: =if(Results!I11="-",0,IF(OR(AND(H12>0,Results!J11>0),AND(H12<0,Results!J11<0),AND(H12=0,Results!J11=0)),1,0)) -> 0 | J12: =IF(K12="-",0,if(K12=Results!I11,3,0)) -> 0 | K12: =E12&"-"&F12 -> 1-1 | L12: =MAX(I12,J12) -> 0
A13: =Results!A12 -> 2 | B13: =Results!B12 -> 46188 | C13: =Results!C12 -> 0.125 | D13: =Results!E12 -> Sweden | E13: 2 | F13: 0 | G13: =Results!H12 -> Tunisia | H13: =E13-F13 -> 2 | I13: =if(Results!I12="-",0,IF(OR(AND(H13>0,Results!J12>0),AND(H13<0,Results!J12<0),AND(H13=0,Results!J12=0)),1,0)) -> 1 | J13: =IF(K13="-",0,if(K13=Results!I12,3,0)) -> 0 | K13: =E13&"-"&F13 -> 2-0 | L13: =MAX(I13,J13) -> 1
... A41: =Results!A40 -> 2 | B41: =Results!B40 -> 46195 | C41: =Results!C40 -> 0.083333333 | D41: =Results!E40 -> New Zealand | E41: 0 | F41: 1 | G41: =Results!H40 -> Egypt | H41: =E41-F41 -> -1 | I41: =if(Results!I40="-",0,IF(OR(AND(H41>0,Results!J40>0),AND(H41<0,Results!J40<0),AND(H41=0,Results!J40=0)),1,0)) -> 0 | J41: =IF(K41="-",0,if(K41=Results!I40,3,0)) -> 0 | K41: =E41&"-"&F41 -> 0-1 | L41: =MAX(I41,J41) -> 0
A42: =Results!A41 -> 2 | B42: =Results!B41 -> 46195 | C42: =Results!C41 -> 0.79166667 | D42: =Results!E41 -> Argentina | G42: =Results!H41 -> Austria | H42: =E42-F42 -> 0 | I42: =if(Results!I41="-",0,IF(OR(AND(H42>0,Results!J41>0),AND(H42<0,Results!J41<0),AND(H42=0,Results!J41=0)),1,0)) -> 0 | J42: =IF(K42="-",0,if(K42=Results!I41,3,0)) -> 0 | K42: =E42&"-"&F42 -> - | L42: =MAX(I42,J42) -> 0
A43: =Results!A42 -> 2 | B43: =Results!B42 -> 46195 | C43: =Results!C42 -> 0.95833333 | D43: =Results!E42 -> France | G43: =Results!H42 -> Iraq | H43: =E43-F43 -> 0 | I43: =if(Results!I42="-",0,IF(OR(AND(H43>0,Results!J42>0),AND(H43<0,Results!J42<0),AND(H43=0,Results!J42=0)),1,0)) -> 0 | J43: =IF(K43="-",0,if(K43=Results!I42,3,0)) -> 0 | K43: =E43&"-"&F43 -> - | L43: =MAX(I43,J43) -> 0
A44: =Results!A43 -> 3 | B44: =Results!B43 -> 46196 | C44: =Results!C43 -> 0.083333333 | D44: =Results!E43 -> Norway | G44: =Results!H43 -> Senegal | H44: =E44-F44 -> 0 | I44: =if(Results!I43="-",0,IF(OR(AND(H44>0,Results!J43>0),AND(H44<0,Results!J43<0),AND(H44=0,Results!J43=0)),1,0)) -> 0 | J44: =IF(K44="-",0,if(K44=Results!I43,3,0)) -> 0 | K44: =E44&"-"&F44 -> - | L44: =MAX(I44,J44) -> 0
A45: =Results!A44 -> 3 | B45: =Results!B44 -> 46196 | C45: =Results!C44 -> 0.20833333 | D45: =Results!E44 -> Jordan | G45: =Results!H44 -> Algeria | H45: =E45-F45 -> 0 | I45: =if(Results!I44="-",0,IF(OR(AND(H45>0,Results!J44>0),AND(H45<0,Results!J44<0),AND(H45=0,Results!J44=0)),1,0)) -> 0 | J45: =IF(K45="-",0,if(K45=Results!I44,3,0)) -> 0 | K45: =E45&"-"&F45 -> - | L45: =MAX(I45,J45) -> 0
A46: =Results!A45 -> 3 | B46: =Results!B45 -> 46196 | C46: =Results!C45 -> 0.79166667 | D46: =Results!E45 -> Portugal | G46: =Results!H45 -> Uzbekistan | H46: =E46-F46 -> 0 | I46: =if(Results!I45="-",0,IF(OR(AND(H46>0,Results!J45>0),AND(H46<0,Results!J45<0),AND(H46=0,Results!J45=0)),1,0)) -> 0 | J46: =IF(K46="-",0,if(K46=Results!I45,3,0)) -> 0 | K46: =E46&"-"&F46 -> - | L46: =MAX(I46,J46) -> 0
A47: =Results!A46 -> 3 | B47: =Results!B46 -> 46196 | C47: =Results!C46 -> 0.91666667 | D47: =Results!E46 -> England | G47: =Results!H46 -> Ghana | H47: =E47-F47 -> 0 | I47: =if(Results!I46="-",0,IF(OR(AND(H47>0,Results!J46>0),AND(H47<0,Results!J46<0),AND(H47=0,Results!J46=0)),1,0)) -> 0 | J47: =IF(K47="-",0,if(K47=Results!I46,3,0)) -> 0 | K47: =E47&"-"&F47 -> - | L47: =MAX(I47,J47) -> 0
A48: =Results!A47 -> 4 | B48: =Results!B47 -> 46197 | C48: =Results!C47 -> 0.041666667 | D48: =Results!E47 -> Panama | G48: =Results!H47 -> Croatia | H48: =E48-F48 -> 0 | I48: =if(Results!I47="-",0,IF(OR(AND(H48>0,Results!J47>0),AND(H48<0,Results!J47<0),AND(H48=0,Results!J47=0)),1,0)) -> 0 | J48: =IF(K48="-",0,if(K48=Results!I47,3,0)) -> 0 | K48: =E48&"-"&F48 -> - | L48: =MAX(I48,J48) -> 0
A49: =Results!A48 -> 4 | B49: =Results!B48 -> 46197 | C49: =Results!C48 -> 0.16666667 | D49: =Results!E48 -> Colombia | G49: =Results!H48 -> DR Congo | H49: =E49-F49 -> 0 | I49: =if(Results!I48="-",0,IF(OR(AND(H49>0,Results!J48>0),AND(H49<0,Results!J48<0),AND(H49=0,Results!J48=0)),1,0)) -> 0 | J49: =IF(K49="-",0,if(K49=Results!I48,3,0)) -> 0 | K49: =E49&"-"&F49 -> - | L49: =MAX(I49,J49) -> 0
A50: =Results!A49 -> 4 | B50: =Results!B49 -> 46197 | C50: =Results!C49 -> 0.75 | D50: =Results!E49 -> Morocco | G50: =Results!H49 -> Haiti | H50: =E50-F50 -> 0 | I50: =if(Results!I49="-",0,IF(OR(AND(H50>0,Results!J49>0),AND(H50<0,Results!J49<0),AND(H50=0,Results!J49=0)),1,0)) -> 0 | J50: =IF(K50="-",0,if(K50=Results!I49,3,0)) -> 0 | K50: =E50&"-"&F50 -> - | L50: =MAX(I50,J50) -> 0
A51: =Results!A50 -> 4 | B51: =Results!B50 -> 46197 | C51: =Results!C50 -> 0.75 | D51: =Results!E50 -> Scotland | G51: =Results!H50 -> Brazil | H51: =E51-F51 -> 0 | I51: =if(Results!I50="-",0,IF(OR(AND(H51>0,Results!J50>0),AND(H51<0,Results!J50<0),AND(H51=0,Results!J50=0)),1,0)) -> 0 | J51: =IF(K51="-",0,if(K51=Results!I50,3,0)) -> 0 | K51: =E51&"-"&F51 -> - | L51: =MAX(I51,J51) -> 0
A52: =Results!A51 -> 4 | B52: =Results!B51 -> 46197 | C52: =Results!C51 -> 0.875 | D52: =Results!E51 -> Canada | G52: =Results!H51 -> Switzerland | H52: =E52-F52 -> 0 | I52: =if(Results!I51="-",0,IF(OR(AND(H52>0,Results!J51>0),AND(H52<0,Results!J51<0),AND(H52=0,Results!J51=0)),1,0)) -> 0 | J52: =IF(K52="-",0,if(K52=Results!I51,3,0)) -> 0 | K52: =E52&"-"&F52 -> - | L52: =MAX(I52,J52) -> 0
A53: =Results!A52 -> 4 | B53: =Results!B52 -> 46197 | C53: =Results!C52 -> 0.875 | D53: =Results!E52 -> Bosnia and Herzegovina | G53: =Results!H52 -> Qatar | H53: =E53-F53 -> 0 | I53: =if(Results!I52="-",0,IF(OR(AND(H53>0,Results!J52>0),AND(H53<0,Results!J52<0),AND(H53=0,Results!J52=0)),1,0)) -> 0 | J53: =IF(K53="-",0,if(K53=Results!I52,3,0)) -> 0 | K53: =E53&"-"&F53 -> - | L53: =MAX(I53,J53) -> 0
... A105: =Results!A104 -> 1 | B105: =Results!B104 -> 46222 | C105: =Results!C104 -> 0.83333333 | D105: =Results!E104 -> Winner Match 101 | G105: =Results!H104 -> Winner Match 102 | H105: =E105-F105 -> 0 | I105: =if(Results!I104="-",0,IF(OR(AND(H105>0,Results!J104>0),AND(H105<0,Results!J104<0),AND(H105=0,Results!J104=0)),1,0)) -> 0 | J105: =IF(K105="-",0,if(K105=Results!I104,3,0)) -> 0 | K105: =E105&"-"&F105 -> - | L105: =MAX(I105,J105) -> 0

Sheet Owen
A2: =Results!A1 -> 5 | B2: =Results!B1 -> 46184 | C2: =Results!C1 -> 0.83333333 | D2: =Results!E1 -> Mexico | E2: 1 | F2: 0 | G2: =Results!H1 -> South Africa | H2: =E2-F2 -> 1 | I2: =if(Results!I1="-",0,IF(OR(AND(H2>0,Results!J1>0),AND(H2<0,Results!J1<0),AND(H2=0,Results!J1=0)),1,0)) -> 1 | J2: =IF(K2="-",0,if(K2=Results!I1,3,0)) -> 0 | K2: =E2&"-"&F2 -> 1-0 | L2: =MAX(I2,J2) -> 1
A3: =Results!A2 -> 6 | B3: =Results!B2 -> 46185 | C3: =Results!C2 -> 0.125 | D3: =Results!E2 -> South Korea | E3: 1 | F3: 1 | G3: =Results!H2 -> Czech Republic | H3: =E3-F3 -> 0 | I3: =if(Results!I2="-",0,IF(OR(AND(H3>0,Results!J2>0),AND(H3<0,Results!J2<0),AND(H3=0,Results!J2=0)),1,0)) -> 0 | J3: =IF(K3="-",0,if(K3=Results!I2,3,0)) -> 0 | K3: =E3&"-"&F3 -> 1-1 | L3: =MAX(I3,J3) -> 0
A4: =Results!A3 -> 6 | B4: =Results!B3 -> 46185 | C4: =Results!C3 -> 0.83333333 | D4: =Results!E3 -> Canada | E4: 1 | F4: 2 | G4: =Results!H3 -> Bosnia and Herzegovina | H4: =E4-F4 -> -1 | I4: =if(Results!I3="-",0,IF(OR(AND(H4>0,Results!J3>0),AND(H4<0,Results!J3<0),AND(H4=0,Results!J3=0)),1,0)) -> 0 | J4: =IF(K4="-",0,if(K4=Results!I3,3,0)) -> 0 | K4: =E4&"-"&F4 -> 1-2 | L4: =MAX(I4,J4) -> 0
A5: =Results!A4 -> 7 | B5: =Results!B4 -> 46186 | C5: =Results!C4 -> 0.083333333 | D5: =Results!E4 -> USA | E5: 1 | F5: 1 | G5: =Results!H4 -> Paraguay | H5: =E5-F5 -> 0 | I5: =if(Results!I4="-",0,IF(OR(AND(H5>0,Results!J4>0),AND(H5<0,Results!J4<0),AND(H5=0,Results!J4=0)),1,0)) -> 0 | J5: =IF(K5="-",0,if(K5=Results!I4,3,0)) -> 0 | K5: =E5&"-"&F5 -> 1-1 | L5: =MAX(I5,J5) -> 0
A6: =Results!A5 -> 7 | B6: =Results!B5 -> 46186 | C6: =Results!C5 -> 0.83333333 | D6: =Results!E5 -> Qatar | E6: 0 | F6: 3 | G6: =Results!H5 -> Switzerland | H6: =E6-F6 -> -3 | I6: =if(Results!I5="-",0,IF(OR(AND(H6>0,Results!J5>0),AND(H6<0,Results!J5<0),AND(H6=0,Results!J5=0)),1,0)) -> 0 | J6: =IF(K6="-",0,if(K6=Results!I5,3,0)) -> 0 | K6: =E6&"-"&F6 -> 0-3 | L6: =MAX(I6,J6) -> 0
A7: =Results!A6 -> 7 | B7: =Results!B6 -> 46186 | C7: =Results!C6 -> 0.95833333 | D7: =Results!E6 -> Brazil | E7: 2 | F7: 1 | G7: =Results!H6 -> Morocco | H7: =E7-F7 -> 1 | I7: =if(Results!I6="-",0,IF(OR(AND(H7>0,Results!J6>0),AND(H7<0,Results!J6<0),AND(H7=0,Results!J6=0)),1,0)) -> 0 | J7: =IF(K7="-",0,if(K7=Results!I6,3,0)) -> 0 | K7: =E7&"-"&F7 -> 2-1 | L7: =MAX(I7,J7) -> 0
A8: =Results!A7 -> 1 | B8: =Results!B7 -> 46187 | C8: =Results!C7 -> 0.083333333 | D8: =Results!E7 -> Haiti | E8: 0 | F8: 3 | G8: =Results!H7 -> Scotland | H8: =E8-F8 -> -3 | I8: =if(Results!I7="-",0,IF(OR(AND(H8>0,Results!J7>0),AND(H8<0,Results!J7<0),AND(H8=0,Results!J7=0)),1,0)) -> 1 | J8: =IF(K8="-",0,if(K8=Results!I7,3,0)) -> 0 | K8: =E8&"-"&F8 -> 0-3 | L8: =MAX(I8,J8) -> 1
A9: =Results!A8 -> 1 | B9: =Results!B8 -> 46187 | C9: =Results!C8 -> 0.20833333 | D9: =Results!E8 -> Australia | E9: 1 | F9: 2 | G9: =Results!H8 -> Türkiye | H9: =E9-F9 -> -1 | I9: =if(Results!I8="-",0,IF(OR(AND(H9>0,Results!J8>0),AND(H9<0,Results!J8<0),AND(H9=0,Results!J8=0)),1,0)) -> 0 | J9: =IF(K9="-",0,if(K9=Results!I8,3,0)) -> 0 | K9: =E9&"-"&F9 -> 1-2 | L9: =MAX(I9,J9) -> 0
A10: =Results!A9 -> 1 | B10: =Results!B9 -> 46187 | C10: =Results!C9 -> 0.75 | D10: =Results!E9 -> Germany | E10: 4 | F10: 0 | G10: =Results!H9 -> Curaçao | H10: =E10-F10 -> 4 | I10: =if(Results!I9="-",0,IF(OR(AND(H10>0,Results!J9>0),AND(H10<0,Results!J9<0),AND(H10=0,Results!J9=0)),1,0)) -> 1 | J10: =IF(K10="-",0,if(K10=Results!I9,3,0)) -> 0 | K10: =E10&"-"&F10 -> 4-0 | L10: =MAX(I10,J10) -> 1
A11: =Results!A10 -> 1 | B11: =Results!B10 -> 46187 | C11: =Results!C10 -> 0.875 | D11: =Results!E10 -> Netherlands | E11: 2 | F11: 1 | G11: =Results!H10 -> Japan | H11: =E11-F11 -> 1 | I11: =if(Results!I10="-",0,IF(OR(AND(H11>0,Results!J10>0),AND(H11<0,Results!J10<0),AND(H11=0,Results!J10=0)),1,0)) -> 0 | J11: =IF(K11="-",0,if(K11=Results!I10,3,0)) -> 0 | K11: =E11&"-"&F11 -> 2-1 | L11: =MAX(I11,J11) -> 0
A12: =Results!A11 -> 2 | B12: =Results!B11 -> 46188 | C12: =Results!C11 -> 0 | D12: =Results!E11 -> Ivory Coast | E12: 2 | F12: 1 | G12: =Results!H11 -> Ecuador | H12: =E12-F12 -> 1 | I12: =if(Results!I11="-",0,IF(OR(AND(H12>0,Results!J11>0),AND(H12<0,Results!J11<0),AND(H12=0,Results!J11=0)),1,0)) -> 1 | J12: =IF(K12="-",0,if(K12=Results!I11,3,0)) -> 0 | K12: =E12&"-"&F12 -> 2-1 | L12: =MAX(I12,J12) -> 1
A13: =Results!A12 -> 2 | B13: =Results!B12 -> 46188 | C13: =Results!C12 -> 0.125 | D13: =Results!E12 -> Sweden | E13: 2 | F13: 0 | G13: =Results!H12 -> Tunisia | H13: =E13-F13 -> 2 | I13: =if(Results!I12="-",0,IF(OR(AND(H13>0,Results!J12>0),AND(H13<0,Results!J12<0),AND(H13=0,Results!J12=0)),1,0)) -> 1 | J13: =IF(K13="-",0,if(K13=Results!I12,3,0)) -> 0 | K13: =E13&"-"&F13 -> 2-0 | L13: =MAX(I13,J13) -> 1
... A49: =Results!A48 -> 4 | B49: =Results!B48 -> 46197 | C49: =Results!C48 -> 0.16666667 | D49: =Results!E48 -> Colombia | E49: 2 | F49: 1 | G49: =Results!H48 -> DR Congo | H49: =E49-F49 -> 1 | I49: =if(Results!I48="-",0,IF(OR(AND(H49>0,Results!J48>0),AND(H49<0,Results!J48<0),AND(H49=0,Results!J48=0)),1,0)) -> 0 | J49: =IF(K49="-",0,if(K49=Results!I48,3,0)) -> 0 | K49: =E49&"-"&F49 -> 2-1 | L49: =MAX(I49,J49) -> 0
A50: =Results!A49 -> 4 | B50: =Results!B49 -> 46197 | C50: =Results!C49 -> 0.75 | D50: =Results!E49 -> Morocco | G50: =Results!H49 -> Haiti | H50: =E50-F50 -> 0 | I50: =if(Results!I49="-",0,IF(OR(AND(H50>0,Results!J49>0),AND(H50<0,Results!J49<0),AND(H50=0,Results!J49=0)),1,0)) -> 0 | J50: =IF(K50="-",0,if(K50=Results!I49,3,0)) -> 0 | K50: =E50&"-"&F50 -> - | L50: =MAX(I50,J50) -> 0
A51: =Results!A50 -> 4 | B51: =Results!B50 -> 46197 | C51: =Results!C50 -> 0.75 | D51: =Results!E50 -> Scotland | G51: =Results!H50 -> Brazil | H51: =E51-F51 -> 0 | I51: =if(Results!I50="-",0,IF(OR(AND(H51>0,Results!J50>0),AND(H51<0,Results!J50<0),AND(H51=0,Results!J50=0)),1,0)) -> 0 | J51: =IF(K51="-",0,if(K51=Results!I50,3,0)) -> 0 | K51: =E51&"-"&F51 -> - | L51: =MAX(I51,J51) -> 0
A52: =Results!A51 -> 4 | B52: =Results!B51 -> 46197 | C52: =Results!C51 -> 0.875 | D52: =Results!E51 -> Canada | G52: =Results!H51 -> Switzerland | H52: =E52-F52 -> 0 | I52: =if(Results!I51="-",0,IF(OR(AND(H52>0,Results!J51>0),AND(H52<0,Results!J51<0),AND(H52=0,Results!J51=0)),1,0)) -> 0 | J52: =IF(K52="-",0,if(K52=Results!I51,3,0)) -> 0 | K52: =E52&"-"&F52 -> - | L52: =MAX(I52,J52) -> 0
A53: =Results!A52 -> 4 | B53: =Results!B52 -> 46197 | C53: =Results!C52 -> 0.875 | D53: =Results!E52 -> Bosnia and Herzegovina | G53: =Results!H52 -> Qatar | H53: =E53-F53 -> 0 | I53: =if(Results!I52="-",0,IF(OR(AND(H53>0,Results!J52>0),AND(H53<0,Results!J52<0),AND(H53=0,Results!J52=0)),1,0)) -> 0 | J53: =IF(K53="-",0,if(K53=Results!I52,3,0)) -> 0 | K53: =E53&"-"&F53 -> - | L53: =MAX(I53,J53) -> 0
A54: =Results!A53 -> 5 | B54: =Results!B53 -> 46198 | C54: =Results!C53 -> 0.083333333 | D54: =Results!E53 -> Mexico | G54: =Results!H53 -> Czechia | H54: =E54-F54 -> 0 | I54: =if(Results!I53="-",0,IF(OR(AND(H54>0,Results!J53>0),AND(H54<0,Results!J53<0),AND(H54=0,Results!J53=0)),1,0)) -> 0 | J54: =IF(K54="-",0,if(K54=Results!I53,3,0)) -> 0 | K54: =E54&"-"&F54 -> - | L54: =MAX(I54,J54) -> 0
A55: =Results!A54 -> 5 | B55: =Results!B54 -> 46198 | C55: =Results!C54 -> 0.083333333 | D55: =Results!E54 -> South Korea | G55: =Results!H54 -> South Africa | H55: =E55-F55 -> 0 | I55: =if(Results!I54="-",0,IF(OR(AND(H55>0,Results!J54>0),AND(H55<0,Results!J54<0),AND(H55=0,Results!J54=0)),1,0)) -> 0 | J55: =IF(K55="-",0,if(K55=Results!I54,3,0)) -> 0 | K55: =E55&"-"&F55 -> - | L55: =MAX(I55,J55) -> 0
A56: =Results!A55 -> 5 | B56: =Results!B55 -> 46198 | C56: =Results!C55 -> 0.75 | D56: =Results!E55 -> Ecuador | G56: =Results!H55 -> Germany | H56: =E56-F56 -> 0 | I56: =if(Results!I55="-",0,IF(OR(AND(H56>0,Results!J55>0),AND(H56<0,Results!J55<0),AND(H56=0,Results!J55=0)),1,0)) -> 0 | J56: =IF(K56="-",0,if(K56=Results!I55,3,0)) -> 0 | K56: =E56&"-"&F56 -> - | L56: =MAX(I56,J56) -> 0
A57: =Results!A56 -> 5 | B57: =Results!B56 -> 46198 | C57: =Results!C56 -> 0.75 | D57: =Results!E56 -> Curaçao | G57: =Results!H56 -> Ivory Coast | H57: =E57-F57 -> 0 | I57: =if(Results!I56="-",0,IF(OR(AND(H57>0,Results!J56>0),AND(H57<0,Results!J56<0),AND(H57=0,Results!J56=0)),1,0)) -> 0 | J57: =IF(K57="-",0,if(K57=Results!I56,3,0)) -> 0 | K57: =E57&"-"&F57 -> - | L57: =MAX(I57,J57) -> 0
A58: =Results!A57 -> 5 | B58: =Results!B57 -> 46198 | C58: =Results!C57 -> 0.875 | D58: =Results!E57 -> Tunisia | G58: =Results!H57 -> Netherlands | H58: =E58-F58 -> 0 | I58: =if(Results!I57="-",0,IF(OR(AND(H58>0,Results!J57>0),AND(H58<0,Results!J57<0),AND(H58=0,Results!J57=0)),1,0)) -> 0 | J58: =IF(K58="-",0,if(K58=Results!I57,3,0)) -> 0 | K58: =E58&"-"&F58 -> - | L58: =MAX(I58,J58) -> 0
A59: =Results!A58 -> 5 | B59: =Results!B58 -> 46198 | C59: =Results!C58 -> 0.875 | D59: =Results!E58 -> Japan | G59: =Results!H58 -> Sweden | H59: =E59-F59 -> 0 | I59: =if(Results!I58="-",0,IF(OR(AND(H59>0,Results!J58>0),AND(H59<0,Results!J58<0),AND(H59=0,Results!J58=0)),1,0)) -> 0 | J59: =IF(K59="-",0,if(K59=Results!I58,3,0)) -> 0 | K59: =E59&"-"&F59 -> - | L59: =MAX(I59,J59) -> 0
A60: =Results!A59 -> 6 | B60: =Results!B59 -> 46199 | C60: =Results!C59 -> 0.041666667 | D60: =Results!E59 -> USA | G60: =Results!H59 -> Türkiye | H60: =E60-F60 -> 0 | I60: =if(Results!I59="-",0,IF(OR(AND(H60>0,Results!J59>0),AND(H60<0,Results!J59<0),AND(H60=0,Results!J59=0)),1,0)) -> 0 | J60: =IF(K60="-",0,if(K60=Results!I59,3,0)) -> 0 | K60: =E60&"-"&F60 -> - | L60: =MAX(I60,J60) -> 0
A61: =Results!A60 -> 6 | B61: =Results!B60 -> 46199 | C61: =Results!C60 -> 0.041666667 | D61: =Results!E60 -> Paraguay | G61: =Results!H60 -> Australia | H61: =E61-F61 -> 0 | I61: =if(Results!I60="-",0,IF(OR(AND(H61>0,Results!J60>0),AND(H61<0,Results!J60<0),AND(H61=0,Results!J60=0)),1,0)) -> 0 | J61: =IF(K61="-",0,if(K61=Results!I60,3,0)) -> 0 | K61: =E61&"-"&F61 -> - | L61: =MAX(I61,J61) -> 0
... A105: =Results!A104 -> 1 | B105: =Results!B104 -> 46222 | C105: =Results!C104 -> 0.83333333 | D105: =Results!E104 -> Winner Match 101 | G105: =Results!H104 -> Winner Match 102 | H105: =E105-F105 -> 0 | I105: =if(Results!I104="-",0,IF(OR(AND(H105>0,Results!J104>0),AND(H105<0,Results!J104<0),AND(H105=0,Results!J104=0)),1,0)) -> 0 | J105: =IF(K105="-",0,if(K105=Results!I104,3,0)) -> 0 | K105: =E105&"-"&F105 -> - | L105: =MAX(I105,J105) -> 0

Sheet Reddy
A2: =Results!A1 -> 5 | B2: =Results!B1 -> 46184 | C2: =Results!C1 -> 0.83333333 | D2: =Results!E1 -> Mexico | E2: 2 | F2: 0 | G2: =Results!H1 -> South Africa | H2: =E2-F2 -> 2 | I2: =if(Results!I1="-",0,IF(OR(AND(H2>0,Results!J1>0),AND(H2<0,Results!J1<0),AND(H2=0,Results!J1=0)),1,0)) -> 1 | J2: =IF(K2="-",0,if(K2=Results!I1,3,0)) -> 3 | K2: =E2&"-"&F2 -> 2-0 | L2: =MAX(I2,J2) -> 3
A3: =Results!A2 -> 6 | B3: =Results!B2 -> 46185 | C3: =Results!C2 -> 0.125 | D3: =Results!E2 -> South Korea | E3: 1 | F3: 2 | G3: =Results!H2 -> Czech Republic | H3: =E3-F3 -> -1 | I3: =if(Results!I2="-",0,IF(OR(AND(H3>0,Results!J2>0),AND(H3<0,Results!J2<0),AND(H3=0,Results!J2=0)),1,0)) -> 0 | J3: =IF(K3="-",0,if(K3=Results!I2,3,0)) -> 0 | K3: =E3&"-"&F3 -> 1-2 | L3: =MAX(I3,J3) -> 0
A4: =Results!A3 -> 6 | B4: =Results!B3 -> 46185 | C4: =Results!C3 -> 0.83333333 | D4: =Results!E3 -> Canada | E4: 2 | F4: 1 | G4: =Results!H3 -> Bosnia and Herzegovina | H4: =E4-F4 -> 1 | I4: =if(Results!I3="-",0,IF(OR(AND(H4>0,Results!J3>0),AND(H4<0,Results!J3<0),AND(H4=0,Results!J3=0)),1,0)) -> 0 | J4: =IF(K4="-",0,if(K4=Results!I3,3,0)) -> 0 | K4: =E4&"-"&F4 -> 2-1 | L4: =MAX(I4,J4) -> 0
A5: =Results!A4 -> 7 | B5: =Results!B4 -> 46186 | C5: =Results!C4 -> 0.083333333 | D5: =Results!E4 -> USA | E5: 2 | F5: 1 | G5: =Results!H4 -> Paraguay | H5: =E5-F5 -> 1 | I5: =if(Results!I4="-",0,IF(OR(AND(H5>0,Results!J4>0),AND(H5<0,Results!J4<0),AND(H5=0,Results!J4=0)),1,0)) -> 1 | J5: =IF(K5="-",0,if(K5=Results!I4,3,0)) -> 0 | K5: =E5&"-"&F5 -> 2-1 | L5: =MAX(I5,J5) -> 1
A6: =Results!A5 -> 7 | B6: =Results!B5 -> 46186 | C6: =Results!C5 -> 0.83333333 | D6: =Results!E5 -> Qatar | E6: 0 | F6: 3 | G6: =Results!H5 -> Switzerland | H6: =E6-F6 -> -3 | I6: =if(Results!I5="-",0,IF(OR(AND(H6>0,Results!J5>0),AND(H6<0,Results!J5<0),AND(H6=0,Results!J5=0)),1,0)) -> 0 | J6: =IF(K6="-",0,if(K6=Results!I5,3,0)) -> 0 | K6: =E6&"-"&F6 -> 0-3 | L6: =MAX(I6,J6) -> 0
A7: =Results!A6 -> 7 | B7: =Results!B6 -> 46186 | C7: =Results!C6 -> 0.95833333 | D7: =Results!E6 -> Brazil | E7: 2 | F7: 1 | G7: =Results!H6 -> Morocco | H7: =E7-F7 -> 1 | I7: =if(Results!I6="-",0,IF(OR(AND(H7>0,Results!J6>0),AND(H7<0,Results!J6<0),AND(H7=0,Results!J6=0)),1,0)) -> 0 | J7: =IF(K7="-",0,if(K7=Results!I6,3,0)) -> 0 | K7: =E7&"-"&F7 -> 2-1 | L7: =MAX(I7,J7) -> 0
A8: =Results!A7 -> 1 | B8: =Results!B7 -> 46187 | C8: =Results!C7 -> 0.083333333 | D8: =Results!E7 -> Haiti | E8: 0 | F8: 2 | G8: =Results!H7 -> Scotland | H8: =E8-F8 -> -2 | I8: =if(Results!I7="-",0,IF(OR(AND(H8>0,Results!J7>0),AND(H8<0,Results!J7<0),AND(H8=0,Results!J7=0)),1,0)) -> 1 | J8: =IF(K8="-",0,if(K8=Results!I7,3,0)) -> 0 | K8: =E8&"-"&F8 -> 0-2 | L8: =MAX(I8,J8) -> 1
A9: =Results!A8 -> 1 | B9: =Results!B8 -> 46187 | C9: =Results!C8 -> 0.20833333 | D9: =Results!E8 -> Australia | E9: 1 | F9: 2 | G9: =Results!H8 -> Türkiye | H9: =E9-F9 -> -1 | I9: =if(Results!I8="-",0,IF(OR(AND(H9>0,Results!J8>0),AND(H9<0,Results!J8<0),AND(H9=0,Results!J8=0)),1,0)) -> 0 | J9: =IF(K9="-",0,if(K9=Results!I8,3,0)) -> 0 | K9: =E9&"-"&F9 -> 1-2 | L9: =MAX(I9,J9) -> 0
A10: =Results!A9 -> 1 | B10: =Results!B9 -> 46187 | C10: =Results!C9 -> 0.75 | D10: =Results!E9 -> Germany | E10: 4 | F10: 0 | G10: =Results!H9 -> Curaçao | H10: =E10-F10 -> 4 | I10: =if(Results!I9="-",0,IF(OR(AND(H10>0,Results!J9>0),AND(H10<0,Results!J9<0),AND(H10=0,Results!J9=0)),1,0)) -> 1 | J10: =IF(K10="-",0,if(K10=Results!I9,3,0)) -> 0 | K10: =E10&"-"&F10 -> 4-0 | L10: =MAX(I10,J10) -> 1
